Workbook
Name ListaFuncionarios: Listas!$A$4:$A$9
Name ListaMotivos: Listas!$B$4:$B$10
Name ListaStatus: Listas!$C$4:$C$5
Name ListaBase: Listas!$D$4:$D$5
Name ListaCategorias: Listas!$E$4:$E$7
Name ListaFornecedores: Listas!$F$4:$F$6
Name ListaMarcas: Listas!$G$4:$G$10
Name Prod_Codigo: 'Cadastro Produtos'!$A$5:$A$54
Name Prod_Nome: 'Cadastro Produtos'!$B$5:$B$54
Name Prod_Marca: 'Cadastro Produtos'!$C$5:$C$54
Name Prod_Categoria: 'Cadastro Produtos'!$D$5:$D$54
Name Prod_Fornecedor: 'Cadastro Produtos'!$E$5:$E$54
Name Prod_PesoMedio: 'Cadastro Produtos'!$F$5:$F$54
Name Prod_CustoCompra: 'Cadastro Produtos'!$G$5:$G$54
Name Prod_PrecoVenda: 'Cadastro Produtos'!$H$5:$H$54
Name Prod_Margem: 'Cadastro Produtos'!$I$5:$I$54
Name Prod_Status: 'Cadastro Produtos'!$J$5:$J$54
Name bEmbalagem: 'Custos Fatiamento'!$B$5
Name vEmbalagem: 'Custos Fatiamento'!$C$5
Name bEtiqueta: 'Custos Fatiamento'!$B$6
Name vEtiqueta: 'Custos Fatiamento'!$C$6
Name bFilme: 'Custos Fatiamento'!$B$7
Name vFilme: 'Custos Fatiamento'!$C$7
Name bEnergia: 'Custos Fatiamento'!$B$8
Name vEnergia: 'Custos Fatiamento'!$C$8
Name bDesgaste: 'Custos Fatiamento'!$B$9
Name vDesgaste: 'Custos Fatiamento'!$C$9
Name bLimpeza: 'Custos Fatiamento'!$B$10
Name vLimpeza: 'Custos Fatiamento'!$C$10
Name bMaoObra: 'Custos Fatiamento'!$B$11
Name vMaoObra: 'Custos Fatiamento'!$C$11
Name MetaPerda: 'Custos Fatiamento'!$B$15
Name MetaPerdaMax: 'Custos Fatiamento'!$B$16
Name Fat_Data: 'Controle Fatiamento'!$A$5:$A$64
Name Fat_Func: 'Controle Fatiamento'!$B$5:$B$64
Name Fat_Produto: 'Controle Fatiamento'!$C$5:$C$64
Name Fat_Marca: 'Controle Fatiamento'!$D$5:$D$64
Name Fat_PesoAntes: 'Controle Fatiamento'!$F$5:$F$64
Name Fat_PesoVend: 'Controle Fatiamento'!$I$5:$I$64
Name Fat_PesoPerd: 'Controle Fatiamento'!$Q$5:$Q$64
Name Fat_ValorPerd: 'Controle Fatiamento'!$S$5:$S$64
Name Fat_Receita: 'Controle Fatiamento'!$AC$5:$AC$64
Name Fat_LucroBruto: 'Controle Fatiamento'!$AD$5:$AD$64
Name Fat_LucroLiq: 'Controle Fatiamento'!$AE$5:$AE$64
Name Fat_Categoria: 'Controle Fatiamento'!$AJ$5:$AJ$64
Name Fat_Fornecedor: 'Controle Fatiamento'!$AK$5:$AK$64
Name Fat_Mes: 'Controle Fatiamento'!$AL$5:$AL$64
Name Base_Prod: 'Base Aux'!$A$5:$A$54
Name Base_ValorPerd: 'Base Aux'!$E$5:$E$54
Name Base_Lucro: 'Base Aux'!$G$5:$G$54
Name Base_KeyPerda: 'Base Aux'!$J$5:$J$54
Name Base_KeyLucro: 'Base Aux'!$K$5:$K$54
Name Base_Func: 'Base Aux'!$N$5:$N$10
Name Base_FuncPerdaPct: 'Base Aux'!$R$5:$R$10
Name Base_FuncValor: 'Base Aux'!$Q$5:$Q$10
Name Base_Forn: 'Base Aux'!$T$5:$T$7
Name Base_FornValor: 'Base Aux'!$W$5:$W$7
Name Base_FornPerdaPct: 'Base Aux'!$X$5:$X$7
Name Base_Mes: 'Base Aux'!$Z$5:$Z$16
Name Base_MesPerda: 'Base Aux'!$AC$5:$AC$16

Sheet Inicio
A1: ED FRIOS - ERP DE FICHA TECNICA E FATIAMENTO
A2: Controle de custo real, perdas e lucro dos produtos fatiados
A4: 1. CADASTRO DE PRODUTOS
A5: Produtos, precos e margens - base de tudo
A7: 2. CUSTOS DO FATIAMENTO
A8: Embalagem, energia, mao de obra e metas
A10: 3. CONTROLE DE FATIAMENTO
A11: Lancamento diario das pecas (aba principal)
A13: 4. DASHBOARD
A14: Indicadores, semaforo, rankings e graficos
A16: 5. RELATORIOS
A17: Totais filtrados por periodo, produto, etc.
A19: Como usar: cadastre os produtos e custos, lance o fatiamento do dia na aba 3 e acompanhe tudo no Dashboard. Celulas amarelas = voce digita; as demais calculam sozinhas e estao protegidas.

Sheet Cadastro Produtos
A1: CADASTRO DE PRODUTOS
A2: Base de todos os calculos. Preencha 1 linha por produto. Campos amarelos = voce digita.
A3: Inicio | B3: Produtos | C3: Custos | D3: Fatiamento | E3: Dashboard | F3: Relatorios
A4: Codigo | B4: Produto | C4: Marca | D4: Categoria | E4: Fornecedor | F4: Peso medio peca (kg) | G4: Custo compra /kg | H4: Preco venda /kg | I4: Margem desejada | J4: Status
A5: P001 | B5: Mussarela | C5: Tirolez | D5: Laticinios | E5: Distribuidora A | F5: 4 | G5: 32 | H5: 44.9 | I5: 0.25 | J5: Ativo
A6: P002 | B6: Presunto Cozido | C6: Sadia | D6: Frios | E6: Distribuidora A | F6: 3.5 | G6: 24 | H6: 36.9 | I6: 0.3 | J6: Ativo
A7: P003 | B7: Mortadela | C7: Seara | D7: Frios | E7: Distribuidora B | F7: 3 | G7: 14 | H7: 22.9 | I7: 0.3 | J7: Ativo
A8: P004 | B8: Queijo Prato | C8: Polenghi | D8: Laticinios | E8: Distribuidora B | F8: 3.8 | G8: 34 | H8: 47.9 | I8: 0.25 | J8: Ativo
A9: P005 | B9: Peito de Peru | C9: Sadia | D9: Frios | E9: Distribuidora C | F9: 2.5 | G9: 38 | H9: 54.9 | I9: 0.28 | J9: Ativo
A10: P006 | B10: Salame Italiano | C10: Perdigao | D10: Embutidos | E10: Distribuidora C | F10: 1.2 | G10: 42 | H10: 64.9 | I10: 0.3 | J10: Ativo
A11: P007 | B11: Bacon | C11: Seara | D11: Defumados | E11: Distribuidora A | F11: 2 | G11: 28 | H11: 42.9 | I11: 0.28 | J11: Ativo
A12: P008 | B12: Queijo Provolone | C12: Tirolez | D12: Laticinios | E12: Distribuidora B | F12: 2.2 | G12: 46 | H12: 66.9 | I12: 0.25 | J12: Ativo

Sheet Custos Fatiamento
A1: CUSTOS FIXOS DO FATIAMENTO
A2: Informe o valor de cada custo e a base (Por kg = multiplica pelo peso vendido; Por peca = aplica 1x por peca aberta).
A3: Inicio | B3: Produtos | C3: Custos | D3: Fatiamento | E3: Dashboard | F3: Relatorios
A4: Item de custo | B4: Base | C4: Valor (R$) | D4: Observacao
A5: Embalagem | B5: Por kg | C5: 0.4 | D5: Bandeja / saco plastico por kg vendido
A6: Etiqueta | B6: Por kg | C6: 0.1 | D6: Etiqueta de balanca por kg vendido
A7: Filme plastico | B7: Por kg | C7: 0.08 | D7: Filme para embalar
A8: Energia | B8: Por peca | C8: 0.5 | D8: Consumo da fatiadora por peca aberta
A9: Desgaste da maquina | B9: Por peca | C9: 0.3 | D9: Manutencao/lamina rateada por peca
A10: Produtos de limpeza | B10: Por peca | C10: 0.2 | D10: Higienizacao por peca
A11: Mao de obra | B11: Por kg | C11: 1.2 | D11: Custo do operador por kg fatiado
A14: PARAMETROS DE META
A15: Meta de perda (%) | B15: 0.05 | C15: Abaixo desta meta = desempenho saudavel
A16: Perda MAXIMA permitida (%) | B16: 0.08 | C16: Acima disso dispara alerta vermelho

Sheet Controle Fatiamento
A1: CONTROLE DE FATIAMENTO
A2: Aba principal. Preencha os campos amarelos; as colunas azuis calculam sozinhas. Congelado ate a coluna Produto.
A3: Inicio | B3: Produtos | C3: Custos | D3: Fatiamento | E3: Dashboard | F3: Relatorios
A4: Data | B4: Funcionario | C4: Produto | D4: Marca | E4: N peca | F4: Peso antes (kg) | G4: Valor pago /kg | H4: Valor total peca | I4: Peso vendido (kg) | J4: Peso descartado (kg) | K4: Peso amostra (kg) | L4: Peso limpeza (kg) | M4: Peso restante (kg) | N4: Motivo das perdas | O4: Preco venda /kg | P4: Observacoes | Q4: Peso perdido (kg) | R4: % perda | S4: Valor perdido | T4: Custo da perda | U4: Custo embalagens | V4: Custo etiquetas | W4: Custo mao de obra | X4: Custo energia | Y4: Outros custos op. | Z4: Custo operacional | AA4: Custo total peca | AB4: Custo real /kg vendido | AC4: Receita | AD4: Lucro bruto | AE4: Lucro liquido | AF4: Margem % | AG4: Markup | AH4: Preco minimo | AI4: Preco ideal (margem) | AJ4: Categoria | AK4: Fornecedor | AL4: Mes
A5: 46204 | B5: Joao | C5: Mussarela | D5: =IF($C5="","",IFERROR(INDEX(Prod_Marca,MATCH($C5,Prod_Nome,0)),"")) | E5: 1 | F5: 4.1 | G5: 32 | H5: =IF($C5="","",$F5*$G5) | I5: 3.6 | J5: 0.18 | K5: 0.05 | L5: 0.07 | M5: 0.2 | N5: Aparas/Casca | O5: =IF($C5="","",IFERROR(INDEX(Prod_PrecoVenda,MATCH($C5,Prod_Nome,0)),0)) | Q5: =IF($C5="","",$J5+$K5+$L5) | R5: =IF($C5="","",IFERROR((Q5)/$F5,0)) | S5: =IF($C5="","",(Q5)*$G5) | T5: =IF($C5="","",(Q5)*$G5) | U5: =IF($C5="","",vEmbalagem*IF(bEmbalagem="Por kg",$I5,1)) | V5: =IF($C5="","",vEtiqueta*IF(bEtiqueta="Por kg",$I5,1)) | W5: =IF($C5="","",vMaoObra*IF(bMaoObra="Por kg",$I5,1)) | X5: =IF($C5="","",vEnergia*IF(bEnergia="Por kg",$I5,1)) | Y5: =IF($C5="","",vFilme*IF(bFilme="Por kg",$I5,1)+vDesgaste*IF(bDesgaste="Por kg",$I5,1)+vLimpeza*IF(bLimpeza="Por kg",$I5,1)) | Z5: =IF($C5="","",U5+V5+W5+X5+Y5) | AA5: =IF($C5="","",H5+Z5) | AB5: =IF($C5="","",IFERROR(AA5/$I5,0)) | AC5: =IF($C5="","",$I5*O5) | AD5: =IF($C5="","",AC5-H5) | AE5: =IF($C5="","",AC5-AA5) | AF5: =IF($C5="","",IFERROR(AE5/AC5,0)) | AG5: =IF($C5="","",IFERROR(O5/AB5,0)) | AH5: =IF($C5="","",AB5) | AI5: =IF($C5="","",IFERROR(AB5/(1-IFERROR(INDEX(Prod_Margem,MATCH($C5,Prod_Nome,0)),0)),0)) | AJ5: =IF($C5="","",IFERROR(INDEX(Prod_Categoria,MATCH($C5,Prod_Nome,0)),"")) | AK5: =IF($C5="","",IFERROR(INDEX(Prod_Fornecedor,MATCH($C5,Prod_Nome,0)),"")) | AL5: =IF($A5="","",DATE(YEAR($A5),MONTH($A5),1))
A6: 46205 | B6: Maria | C6: Presunto Cozido | D6: =IF($C6="","",IFERROR(INDEX(Prod_Marca,MATCH($C6,Prod_Nome,0)),"")) | E6: 2 | F6: 3.6 | G6: 24 | H6: =IF($C6="","",$F6*$G6) | I6: 3.2 | J6: 0.12 | K6: 0.06 | L6: 0.05 | M6: 0.17 | N6: Ponta da peca | O6: =IF($C6="","",IFERROR(INDEX(Prod_PrecoVenda,MATCH($C6,Prod_Nome,0)),0)) | Q6: =IF($C6="","",$J6+$K6+$L6) | R6: =IF($C6="","",IFERROR((Q6)/$F6,0)) | S6: =IF($C6="","",(Q6)*$G6) | T6: =IF($C6="","",(Q6)*$G6) | U6: =IF($C6="","",vEmbalagem*IF(bEmbalagem="Por kg",$I6,1)) | V6: =IF($C6="","",vEtiqueta*IF(bEtiqueta="Por kg",$I6,1)) | W6: =IF($C6="","",vMaoObra*IF(bMaoObra="Por kg",$I6,1)) | X6: =IF($C6="","",vEnergia*IF(bEnergia="Por kg",$I6,1)) | Y6: =IF($C6="","",vFilme*IF(bFilme="Por kg",$I6,1)+vDesgaste*IF(bDesgaste="Por kg",$I6,1)+vLimpeza*IF(bLimpeza="Por kg",$I6,1)) | Z6: =IF($C6="","",U6+V6+W6+X6+Y6) | AA6: =IF($C6="","",H6+Z6) | AB6: =IF($C6="","",IFERROR(AA6/$I6,0)) | AC6: =IF($C6="","",$I6*O6) | AD6: =IF($C6="","",AC6-H6) | AE6: =IF($C6="","",AC6-AA6) | AF6: =IF($C6="","",IFERROR(AE6/AC6,0)) | AG6: =IF($C6="","",IFERROR(O6/AB6,0)) | AH6: =IF($C6="","",AB6) | AI6: =IF($C6="","",IFERROR(AB6/(1-IFERROR(INDEX(Prod_Margem,MATCH($C6,Prod_Nome,0)),0)),0)) | AJ6: =IF($C6="","",IFERROR(INDEX(Prod_Categoria,MATCH($C6,Prod_Nome,0)),"")) | AK6: =IF($C6="","",IFERROR(INDEX(Prod_Fornecedor,MATCH($C6,Prod_Nome,0)),"")) | AL6: =IF($A6="","",DATE(YEAR($A6),MONTH($A6),1))
A7: 46206 | B7: Carlos | C7: Mortadela | D7: =IF($C7="","",IFERROR(INDEX(Prod_Marca,MATCH($C7,Prod_Nome,0)),"")) | E7: 3 | F7: 3.05 | G7: 14 | H7: =IF($C7="","",$F7*$G7) | I7: 2.55 | J7: 0.2 | K7: 0.08 | L7: 0.06 | M7: 0.16 | N7: Aparas/Casca | O7: =IF($C7="","",IFERROR(INDEX(Prod_PrecoVenda,MATCH($C7,Prod_Nome,0)),0)) | P7: Peca com muita casca | Q7: =IF($C7="","",$J7+$K7+$L7) | R7: =IF($C7="","",IFERROR((Q7)/$F7,0)) | S7: =IF($C7="","",(Q7)*$G7) | T7: =IF($C7="","",(Q7)*$G7) | U7: =IF($C7="","",vEmbalagem*IF(bEmbalagem="Por kg",$I7,1)) | V7: =IF($C7="","",vEtiqueta*IF(bEtiqueta="Por kg",$I7,1)) | W7: =IF($C7="","",vMaoObra*IF(bMaoObra="Por kg",$I7,1)) | X7: =IF($C7="","",vEnergia*IF(bEnergia="Por kg",$I7,1)) | Y7: =IF($C7="","",vFilme*IF(bFilme="Por kg",$I7,1)+vDesgaste*IF(bDesgaste="Por kg",$I7,1)+vLimpeza*IF(bLimpeza="Por kg",$I7,1)) | Z7: =IF($C7="","",U7+V7+W7+X7+Y7) | AA7: =IF($C7="","",H7+Z7) | AB7: =IF($C7="","",IFERROR(AA7/$I7,0)) | AC7: =IF($C7="","",$I7*O7) | AD7: =IF($C7="","",AC7-H7) | AE7: =IF($C7="","",AC7-AA7) | AF7: =IF($C7="","",IFERROR(AE7/AC7,0)) | AG7: =IF($C7="","",IFERROR(O7/AB7,0)) | AH7: =IF($C7="","",AB7) | AI7: =IF($C7="","",IFERROR(AB7/(1-IFERROR(INDEX(Prod_Margem,MATCH($C7,Prod_Nome,0)),0)),0)) | AJ7: =IF($C7="","",IFERROR(INDEX(Prod_Categoria,MATCH($C7,Prod_Nome,0)),"")) | AK7: =IF($C7="","",IFERROR(INDEX(Prod_Fornecedor,MATCH($C7,Prod_Nome,0)),"")) | AL7: =IF($A7="","",DATE(YEAR($A7),MONTH($A7),1))
A8: 46208 | B8: Ana | C8: Queijo Prato | D8: =IF($C8="","",IFERROR(INDEX(Prod_Marca,MATCH($C8,Prod_Nome,0)),"")) | E8: 4 | F8: 3.8 | G8: 34 | H8: =IF($C8="","",$F8*$G8) | I8: 3.45 | J8: 0.1 | K8: 0.04 | L8: 0.05 | M8: 0.16 | N8: Amostra ao cliente | O8: =IF($C8="","",IFERROR(INDEX(Prod_PrecoVenda,MATCH($C8,Prod_Nome,0)),0)) | Q8: =IF($C8="","",$J8+$K8+$L8) | R8: =IF($C8="","",IFERROR((Q8)/$F8,0)) | S8: =IF($C8="","",(Q8)*$G8) | T8: =IF($C8="","",(Q8)*$G8) | U8: =IF($C8="","",vEmbalagem*IF(bEmbalagem="Por kg",$I8,1)) | V8: =IF($C8="","",vEtiqueta*IF(bEtiqueta="Por kg",$I8,1)) | W8: =IF($C8="","",vMaoObra*IF(bMaoObra="Por kg",$I8,1)) | X8: =IF($C8="","",vEnergia*IF(bEnergia="Por kg",$I8,1)) | Y8: =IF($C8="","",vFilme*IF(bFilme="Por kg",$I8,1)+vDesgaste*IF(bDesgaste="Por kg",$I8,1)+vLimpeza*IF(bLimpeza="Por kg",$I8,1)) | Z8: =IF($C8="","",U8+V8+W8+X8+Y8) | AA8: =IF($C8="","",H8+Z8) | AB8: =IF($C8="","",IFERROR(AA8/$I8,0)) | AC8: =IF($C8="","",$I8*O8) | AD8: =IF($C8="","",AC8-H8) | AE8: =IF($C8="","",AC8-AA8) | AF8: =IF($C8="","",IFERROR(AE8/AC8,0)) | AG8: =IF($C8="","",IFERROR(O8/AB8,0)) | AH8: =IF($C8="","",AB8) | AI8: =IF($C8="","",IFERROR(AB8/(1-IFERROR(INDEX(Prod_Margem,MATCH($C8,Prod_Nome,0)),0)),0)) | AJ8: =IF($C8="","",IFERROR(INDEX(Prod_Categoria,MATCH($C8,Prod_Nome,0)),"")) | AK8: =IF($C8="","",IFERROR(INDEX(Prod_Fornecedor,MATCH($C8,Prod_Nome,0)),"")) | AL8: =IF($A8="","",DATE(YEAR($A8),MONTH($A8),1))
A9: 46209 | B9: Joao | C9: Peito de Peru | D9: =IF($C9="","",IFERROR(INDEX(Prod_Marca,MATCH($C9,Prod_Nome,0)),"")) | E9: 5 | F9: 2.55 | G9: 38 | H9: =IF($C9="","",$F9*$G9) | I9: 2.25 | J9: 0.09 | K9: 0.05 | L9: 0.04 | M9: 0.12 | N9: Ponta da peca | O9: =IF($C9="","",IFERROR(INDEX(Prod_PrecoVenda,MATCH($C9,Prod_Nome,0)),0)) | Q9: =IF($C9="","",$J9+$K9+$L9) | R9: =IF($C9="","",IFERROR((Q9)/$F9,0)) | S9: =IF($C9="","",(Q9)*$G9) | T9: =IF($C9="","",(Q9)*$G9) | U9: =IF($C9="","",vEmbalagem*IF(bEmbalagem="Por kg",$I9,1)) | V9: =IF($C9="","",vEtiqueta*IF(bEtiqueta="Por kg",$I9,1)) | W9: =IF($C9="","",vMaoObra*IF(bMaoObra="Por kg",$I9,1)) | X9: =IF($C9="","",vEnergia*IF(bEnergia="Por kg",$I9,1)) | Y9: =IF($C9="","",vFilme*IF(bFilme="Por kg",$I9,1)+vDesgaste*IF(bDesgaste="Por kg",$I9,1)+vLimpeza*IF(bLimpeza="Por kg",$I9,1)) | Z9: =IF($C9="","",U9+V9+W9+X9+Y9) | AA9: =IF($C9="","",H9+Z9) | AB9: =IF($C9="","",IFERROR(AA9/$I9,0)) | AC9: =IF($C9="","",$I9*O9) | AD9: =IF($C9="","",AC9-H9) | AE9: =IF($C9="","",AC9-AA9) | AF9: =IF($C9="","",IFERROR(AE9/AC9,0)) | AG9: =IF($C9="","",IFERROR(O9/AB9,0)) | AH9: =IF($C9="","",AB9) | AI9: =IF($C9="","",IFERROR(AB9/(1-IFERROR(INDEX(Prod_Margem,MATCH($C9,Prod_Nome,0)),0)),0)) | AJ9: =IF($C9="","",IFERROR(INDEX(Prod_Categoria,MATCH($C9,Prod_Nome,0)),"")) | AK9: =IF($C9="","",IFERROR(INDEX(Prod_Fornecedor,MATCH($C9,Prod_Nome,0)),"")) | AL9: =IF($A9="","",DATE(YEAR($A9),MONTH($A9),1))
A10: 46211 | B10: Pedro | C10: Salame Italiano | D10: =IF($C10="","",IFERROR(INDEX(Prod_Marca,MATCH($C10,Prod_Nome,0)),"")) | E10: 6 | F10: 1.25 | G10: 42 | H10: =IF($C10="","",$F10*$G10) | I10: 1 | J10: 0.1 | K10: 0.03 | L10: 0.04 | M10: 0.08 | N10: Validade proxima | O10: =IF($C10="","",IFERROR(INDEX(Prod_PrecoVenda,MATCH($C10,Prod_Nome,0)),0)) | P10: Girou devagar | Q10: =IF($C10="","",$J10+$K10+$L10) | R10: =IF($C10="","",IFERROR((Q10)/$F10,0)) | S10: =IF($C10="","",(Q10)*$G10) | T10: =IF($C10="","",(Q10)*$G10) | U10: =IF($C10="","",vEmbalagem*IF(bEmbalagem="Por kg",$I10,1)) | V10: =IF($C10="","",vEtiqueta*IF(bEtiqueta="Por kg",$I10,1)) | W10: =IF($C10="","",vMaoObra*IF(bMaoObra="Por kg",$I10,1)) | X10: =IF($C10="","",vEnergia*IF(bEnergia="Por kg",$I10,1)) | Y10: =IF($C10="","",vFilme*IF(bFilme="Por kg",$I10,1)+vDesgaste*IF(bDesgaste="Por kg",$I10,1)+vLimpeza*IF(bLimpeza="Por kg",$I10,1)) | Z10: =IF($C10="","",U10+V10+W10+X10+Y10) | AA10: =IF($C10="","",H10+Z10) | AB10: =IF($C10="","",IFERROR(AA10/$I10,0)) | AC10: =IF($C10="","",$I10*O10) | AD10: =IF($C10="","",AC10-H10) | AE10: =IF($C10="","",AC10-AA10) | AF10: =IF($C10="","",IFERROR(AE10/AC10,0)) | AG10: =IF($C10="","",IFERROR(O10/AB10,0)) | AH10: =IF($C10="","",AB10) | AI10: =IF($C10="","",IFERROR(AB10/(1-IFERROR(INDEX(Prod_Margem,MATCH($C10,Prod_Nome,0)),0)),0)) | AJ10: =IF($C10="","",IFERROR(INDEX(Prod_Categoria,MATCH($C10,Prod_Nome,0)),"")) | AK10: =IF($C10="","",IFERROR(INDEX(Prod_Fornecedor,MATCH($C10,Prod_Nome,0)),"")) | AL10: =IF($A10="","",DATE(YEAR($A10),MONTH($A10),1))
A11: 46213 | B11: Maria | C11: Bacon | D11: =IF($C11="","",IFERROR(INDEX(Prod_Marca,MATCH($C11,Prod_Nome,0)),"")) | E11: 7 | F11: 2.05 | G11: 28 | H11: =IF($C11="","",$F11*$G11) | I11: 1.75 | J11: 0.12 | K11: 0.03 | L11: 0.05 | M11: 0.1 | N11: Aparas/Casca | O11: =IF($C11="","",IFERROR(INDEX(Prod_PrecoVenda,MATCH($C11,Prod_Nome,0)),0)) | Q11: =IF($C11="","",$J11+$K11+$L11) | R11: =IF($C11="","",IFERROR((Q11)/$F11,0)) | S11: =IF($C11="","",(Q11)*$G11) | T11: =IF($C11="","",(Q11)*$G11) | U11: =IF($C11="","",vEmbalagem*IF(bEmbalagem="Por kg",$I11,1)) | V11: =IF($C11="","",vEtiqueta*IF(bEtiqueta="Por kg",$I11,1)) | W11: =IF($C11="","",vMaoObra*IF(bMaoObra="Por kg",$I11,1)) | X11: =IF($C11="","",vEnergia*IF(bEnergia="Por kg",$I11,1)) | Y11: =IF($C11="","",vFilme*IF(bFilme="Por kg",$I11,1)+vDesgaste*IF(bDesgaste="Por kg",$I11,1)+vLimpeza*IF(bLimpeza="Por kg",$I11,1)) | Z11: =IF($C11="","",U11+V11+W11+X11+Y11) | AA11: =IF($C11="","",H11+Z11) | AB11: =IF($C11="","",IFERROR(AA11/$I11,0)) | AC11: =IF($C11="","",$I11*O11) | AD11: =IF($C11="","",AC11-H11) | AE11: =IF($C11="","",AC11-AA11) | AF11: =IF($C11="","",IFERROR(AE11/AC11,0)) | AG11: =IF($C11="","",IFERROR(O11/AB11,0)) | AH11: =IF($C11="","",AB11) | AI11: =IF($C11="","",IFERROR(AB11/(1-IFERROR(INDEX(Prod_Margem,MATCH($C11,Prod_Nome,0)),0)),0)) | AJ11: =IF($C11="","",IFERROR(INDEX(Prod_Categoria,MATCH($C11,Prod_Nome,0)),"")) | AK11: =IF($C11="","",IFERROR(INDEX(Prod_Fornecedor,MATCH($C11,Prod_Nome,0)),"")) | AL11: =IF($A11="","",DATE(YEAR($A11),MONTH($A11),1))
A12: 46215 | B12: Carlos | C12: Queijo Provolone | D12: =IF($C12="","",IFERROR(INDEX(Prod_Marca,MATCH($C12,Prod_Nome,0)),"")) | E12: 8 | F12: 2.25 | G12: 46 | H12: =IF($C12="","",$F12*$G12) | I12: 1.98 | J12: 0.11 | K12: 0.04 | L12: 0.04 | M12: 0.08 | N12: Ponta da peca | O12: =IF($C12="","",IFERROR(INDEX(Prod_PrecoVenda,MATCH($C12,Prod_Nome,0)),0)) | Q12: =IF($C12="","",$J12+$K12+$L12) | R12: =IF($C12="","",IFERROR((Q12)/$F12,0)) | S12: =IF($C12="","",(Q12)*$G12) | T12: =IF($C12="","",(Q12)*$G12) | U12: =IF($C12="","",vEmbalagem*IF(bEmbalagem="Por kg",$I12,1)) | V12: =IF($C12="","",vEtiqueta*IF(bEtiqueta="Por kg",$I12,1)) | W12: =IF($C12="","",vMaoObra*IF(bMaoObra="Por kg",$I12,1)) | X12: =IF($C12="","",vEnergia*IF(bEnergia="Por kg",$I12,1)) | Y12: =IF($C12="","",vFilme*IF(bFilme="Por kg",$I12,1)+vDesgaste*IF(bDesgaste="Por kg",$I12,1)+vLimpeza*IF(bLimpeza="Por kg",$I12,1)) | Z12: =IF($C12="","",U12+V12+W12+X12+Y12) | AA12: =IF($C12="","",H12+Z12) | AB12: =IF($C12="","",IFERROR(AA12/$I12,0)) | AC12: =IF($C12="","",$I12*O12) | AD12: =IF($C12="","",AC12-H12) | AE12: =IF($C12="","",AC12-AA12) | AF12: =IF($C12="","",IFERROR(AE12/AC12,0)) | AG12: =IF($C12="","",IFERROR(O12/AB12,0)) | AH12: =IF($C12="","",AB12) | AI12: =IF($C12="","",IFERROR(AB12/(1-IFERROR(INDEX(Prod_Margem,MATCH($C12,Prod_Nome,0)),0)),0)) | AJ12: =IF($C12="","",IFERROR(INDEX(Prod_Categoria,MATCH($C12,Prod_Nome,0)),"")) | AK12: =IF($C12="","",IFERROR(INDEX(Prod_Fornecedor,MATCH($C12,Prod_Nome,0)),"")) | AL12: =IF($A12="","",DATE(YEAR($A12),MONTH($A12),1))
A13: 46217 | B13: Ana | C13: Mussarela | D13: =IF($C13="","",IFERROR(INDEX(Prod_Marca,MATCH($C13,Prod_Nome,0)),"")) | E13: 9 | F13: 4.05 | G13: 32 | H13: =IF($C13="","",$F13*$G13) | I13: 3.55 | J13: 0.16 | K13: 0.05 | L13: 0.06 | M13: 0.23 | N13: Aparas/Casca | O13: =IF($C13="","",IFERROR(INDEX(Prod_PrecoVenda,MATCH($C13,Prod_Nome,0)),0)) | Q13: =IF($C13="","",$J13+$K13+$L13) | R13: =IF($C13="","",IFERROR((Q13)/$F13,0)) | S13: =IF($C13="","",(Q13)*$G13) | T13: =IF($C13="","",(Q13)*$G13) | U13: =IF($C13="","",vEmbalagem*IF(bEmbalagem="Por kg",$I13,1)) | V13: =IF($C13="","",vEtiqueta*IF(bEtiqueta="Por kg",$I13,1)) | W13: =IF($C13="","",vMaoObra*IF(bMaoObra="Por kg",$I13,1)) | X13: =IF($C13="","",vEnergia*IF(bEnergia="Por kg",$I13,1)) | Y13: =IF($C13="","",vFilme*IF(bFilme="Por kg",$I13,1)+vDesgaste*IF(bDesgaste="Por kg",$I13,1)+vLimpeza*IF(bLimpeza="Por kg",$I13,1)) | Z13: =IF($C13="","",U13+V13+W13+X13+Y13) | AA13: =IF($C13="","",H13+Z13) | AB13: =IF($C13="","",IFERROR(AA13/$I13,0)) | AC13: =IF($C13="","",$I13*O13) | AD13: =IF($C13="","",AC13-H13) | AE13: =IF($C13="","",AC13-AA13) | AF13: =IF($C13="","",IFERROR(AE13/AC13,0)) | AG13: =IF($C13="","",IFERROR(O13/AB13,0)) | AH13: =IF($C13="","",AB13) | AI13: =IF($C13="","",IFERROR(AB13/(1-IFERROR(INDEX(Prod_Margem,MATCH($C13,Prod_Nome,0)),0)),0)) | AJ13: =IF($C13="","",IFERROR(INDEX(Prod_Categoria,MATCH($C13,Prod_Nome,0)),"")) | AK13: =IF($C13="","",IFERROR(INDEX(Prod_Fornecedor,MATCH($C13,Prod_Nome,0)),"")) | AL13: =IF($A13="","",DATE(YEAR($A13),MONTH($A13),1))
A14: 46219 | B14: Joao | C14: Mortadela | D14: =IF($C14="","",IFERROR(INDEX(Prod_Marca,MATCH($C14,Prod_Nome,0)),"")) | E14: 10 | F14: 3.1 | G14: 14 | H14: =IF($C14="","",$F14*$G14) | I14: 2.4 | J14: 0.28 | K14: 0.1 | L14: 0.08 | M14: 0.24 | N14: Produto danificado | O14: =IF($C14="","",IFERROR(INDEX(Prod_PrecoVenda,MATCH($C14,Prod_Nome,0)),0)) | P14: Perda alta - conferir | Q14: =IF($C14="","",$J14+$K14+$L14) | R14: =IF($C14="","",IFERROR((Q14)/$F14,0)) | S14: =IF($C14="","",(Q14)*$G14) | T14: =IF($C14="","",(Q14)*$G14) | U14: =IF($C14="","",vEmbalagem*IF(bEmbalagem="Por kg",$I14,1)) | V14: =IF($C14="","",vEtiqueta*IF(bEtiqueta="Por kg",$I14,1)) | W14: =IF($C14="","",vMaoObra*IF(bMaoObra="Por kg",$I14,1)) | X14: =IF($C14="","",vEnergia*IF(bEnergia="Por kg",$I14,1)) | Y14: =IF($C14="","",vFilme*IF(bFilme="Por kg",$I14,1)+vDesgaste*IF(bDesgaste="Por kg",$I14,1)+vLimpeza*IF(bLimpeza="Por kg",$I14,1)) | Z14: =IF($C14="","",U14+V14+W14+X14+Y14) | AA14: =IF($C14="","",H14+Z14) | AB14: =IF($C14="","",IFERROR(AA14/$I14,0)) | AC14: =IF($C14="","",$I14*O14) | AD14: =IF($C14="","",AC14-H14) | AE14: =IF($C14="","",AC14-AA14) | AF14: =IF($C14="","",IFERROR(AE14/AC14,0)) | AG14: =IF($C14="","",IFERROR(O14/AB14,0)) | AH14: =IF($C14="","",AB14) | AI14: =IF($C14="","",IFERROR(AB14/(1-IFERROR(INDEX(Prod_Margem,MATCH($C14,Prod_Nome,0)),0)),0)) | AJ14: =IF($C14="","",IFERROR(INDEX(Prod_Categoria,MATCH($C14,Prod_Nome,0)),"")) | AK14: =IF($C14="","",IFERROR(INDEX(Prod_Fornecedor,MATCH($C14,Prod_Nome,0)),"")) | AL14: =IF($A14="","",DATE(YEAR($A14),MONTH($A14),1))
A15: 46221 | B15: Pedro | C15: Presunto Cozido | D15: =IF($C15="","",IFERROR(INDEX(Prod_Marca,MATCH($C15,Prod_Nome,0)),"")) | E15: 11 | F15: 3.55 | G15: 24 | H15: =IF($C15="","",$F15*$G15) | I15: 3.15 | J15: 0.13 | K15: 0.05 | L15: 0.05 | M15: 0.17 | N15: Ponta da peca | O15: =IF($C15="","",IFERROR(INDEX(Prod_PrecoVenda,MATCH($C15,Prod_Nome,0)),0)) | Q15: =IF($C15="","",$J15+$K15+$L15) | R15: =IF($C15="","",IFERROR((Q15)/$F15,0)) | S15: =IF($C15="","",(Q15)*$G15) | T15: =IF($C15="","",(Q15)*$G15) | U15: =IF($C15="","",vEmbalagem*IF(bEmbalagem="Por kg",$I15,1)) | V15: =IF($C15="","",vEtiqueta*IF(bEtiqueta="Por kg",$I15,1)) | W15: =IF($C15="","",vMaoObra*IF(bMaoObra="Por kg",$I15,1)) | X15: =IF($C15="","",vEnergia*IF(bEnergia="Por kg",$I15,1)) | Y15: =IF($C15="","",vFilme*IF(bFilme="Por kg",$I15,1)+vDesgaste*IF(bDesgaste="Por kg",$I15,1)+vLimpeza*IF(bLimpeza="Por kg",$I15,1)) | Z15: =IF($C15="","",U15+V15+W15+X15+Y15) | AA15: =IF($C15="","",H15+Z15) | AB15: =IF($C15="","",IFERROR(AA15/$I15,0)) | AC15: =IF($C15="","",$I15*O15) | AD15: =IF($C15="","",AC15-H15) | AE15: =IF($C15="","",AC15-AA15) | AF15: =IF($C15="","",IFERROR(AE15/AC15,0)) | AG15: =IF($C15="","",IFERROR(O15/AB15,0)) | AH15: =IF($C15="","",AB15) | AI15: =IF($C15="","",IFERROR(AB15/(1-IFERROR(INDEX(Prod_Margem,MATCH($C15,Prod_Nome,0)),0)),0)) | AJ15: =IF($C15="","",IFERROR(INDEX(Prod_Categoria,MATCH($C15,Prod_Nome,0)),"")) | AK15: =IF($C15="","",IFERROR(INDEX(Prod_Fornecedor,MATCH($C15,Prod_Nome,0)),"")) | AL15: =IF($A15="","",DATE(YEAR($A15),MONTH($A15),1))
A16: 46223 | B16: Maria | C16: Peito de Peru | D16: =IF($C16="","",IFERROR(INDEX(Prod_Marca,MATCH($C16,Prod_Nome,0)),"")) | E16: 12 | F16: 2.5 | G16: 38 | H16: =IF($C16="","",$F16*$G16) | I16: 2.28 | J16: 0.08 | K16: 0.04 | L16: 0.03 | M16: 0.07 | N16: Amostra ao cliente | O16: =IF($C16="","",IFERROR(INDEX(Prod_PrecoVenda,MATCH($C16,Prod_Nome,0)),0)) | Q16: =IF($C16="","",$J16+$K16+$L16) | R16: =IF($C16="","",IFERROR((Q16)/$F16,0)) | S16: =IF($C16="","",(Q16)*$G16) | T16: =IF($C16="","",(Q16)*$G16) | U16: =IF($C16="","",vEmbalagem*IF(bEmbalagem="Por kg",$I16,1)) | V16: =IF($C16="","",vEtiqueta*IF(bEtiqueta="Por kg",$I16,1)) | W16: =IF($C16="","",vMaoObra*IF(bMaoObra="Por kg",$I16,1)) | X16: =IF($C16="","",vEnergia*IF(bEnergia="Por kg",$I16,1)) | Y16: =IF($C16="","",vFilme*IF(bFilme="Por kg",$I16,1)+vDesgaste*IF(bDesgaste="Por kg",$I16,1)+vLimpeza*IF(bLimpeza="Por kg",$I16,1)) | Z16: =IF($C16="","",U16+V16+W16+X16+Y16) | AA16: =IF($C16="","",H16+Z16) | AB16: =IF($C16="","",IFERROR(AA16/$I16,0)) | AC16: =IF($C16="","",$I16*O16) | AD16: =IF($C16="","",AC16-H16) | AE16: =IF($C16="","",AC16-AA16) | AF16: =IF($C16="","",IFERROR(AE16/AC16,0)) | AG16: =IF($C16="","",IFERROR(O16/AB16,0)) | AH16: =IF($C16="","",AB16) | AI16: =IF($C16="","",IFERROR(AB16/(1-IFERROR(INDEX(Prod_Margem,MATCH($C16,Prod_Nome,0)),0)),0)) | AJ16: =IF($C16="","",IFERROR(INDEX(Prod_Categoria,MATCH($C16,Prod_Nome,0)),"")) | AK16: =IF($C16="","",IFERROR(INDEX(Prod_Fornecedor,MATCH($C16,Prod_Nome,0)),"")) | AL16: =IF($A16="","",DATE(YEAR($A16),MONTH($A16),1))
A17: 46224 | B17: Rafael | C17: Bacon | D17: =IF($C17="","",IFERROR(INDEX(Prod_Marca,MATCH($C17,Prod_Nome,0)),"")) | E17: 13 | F17: 2 | G17: 28 | H17: =IF($C17="","",$F17*$G17) | I17: 1.6 | J17: 0.18 | K17: 0.04 | L17: 0.06 | M17: 0.12 | N17: Produto danificado | O17: =IF($C17="","",IFERROR(INDEX(Prod_PrecoVenda,MATCH($C17,Prod_Nome,0)),0)) | P17: Ressecou | Q17: =IF($C17="","",$J17+$K17+$L17) | R17: =IF($C17="","",IFERROR((Q17)/$F17,0)) | S17: =IF($C17="","",(Q17)*$G17) | T17: =IF($C17="","",(Q17)*$G17) | U17: =IF($C17="","",vEmbalagem*IF(bEmbalagem="Por kg",$I17,1)) | V17: =IF($C17="","",vEtiqueta*IF(bEtiqueta="Por kg",$I17,1)) | W17: =IF($C17="","",vMaoObra*IF(bMaoObra="Por kg",$I17,1)) | X17: =IF($C17="","",vEnergia*IF(bEnergia="Por kg",$I17,1)) | Y17: =IF($C17="","",vFilme*IF(bFilme="Por kg",$I17,1)+vDesgaste*IF(bDesgaste="Por kg",$I17,1)+vLimpeza*IF(bLimpeza="Por kg",$I17,1)) | Z17: =IF($C17="","",U17+V17+W17+X17+Y17) | AA17: =IF($C17="","",H17+Z17) | AB17: =IF($C17="","",IFERROR(AA17/$I17,0)) | AC17: =IF($C17="","",$I17*O17) | AD17: =IF($C17="","",AC17-H17) | AE17: =IF($C17="","",AC17-AA17) | AF17: =IF($C17="","",IFERROR(AE17/AC17,0)) | AG17: =IF($C17="","",IFERROR(O17/AB17,0)) | AH17: =IF($C17="","",AB17) | AI17: =IF($C17="","",IFERROR(AB17/(1-IFERROR(INDEX(Prod_Margem,MATCH($C17,Prod_Nome,0)),0)),0)) | AJ17: =IF($C17="","",IFERROR(INDEX(Prod_Categoria,MATCH($C17,Prod_Nome,0)),"")) | AK17: =IF($C17="","",IFERROR(INDEX(Prod_Fornecedor,MATCH($C17,Prod_Nome,0)),"")) | AL17: =IF($A17="","",DATE(YEAR($A17),MONTH($A17),1))
A18: 46225 | B18: Ana | C18: Queijo Prato | D18: =IF($C18="","",IFERROR(INDEX(Prod_Marca,MATCH($C18,Prod_Nome,0)),"")) | E18: 14 | F18: 3.75 | G18: 34 | H18: =IF($C18="","",$F18*$G18) | I18: 3.4 | J18: 0.1 | K18: 0.05 | L18: 0.05 | M18: 0.15 | N18: Aparas/Casca | O18: =IF($C18="","",IFERROR(INDEX(Prod_PrecoVenda,MATCH($C18,Prod_Nome,0)),0)) | Q18: =IF($C18="","",$J18+$K18+$L18) | R18: =IF($C18="","",IFERROR((Q18)/$F18,0)) | S18: =IF($C18="","",(Q18)*$G18) | T18: =IF($C18="","",(Q18)*$G18) | U18: =IF($C18="","",vEmbalagem*IF(bEmbalagem="Por kg",$I18,1)) | V18: =IF($C18="","",vEtiqueta*IF(bEtiqueta="Por kg",$I18,1)) | W18: =IF($C18="","",vMaoObra*IF(bMaoObra="Por kg",$I18,1)) | X18: =IF($C18="","",vEnergia*IF(bEnergia="Por kg",$I18,1)) | Y18: =IF($C18="","",vFilme*IF(bFilme="Por kg",$I18,1)+vDesgaste*IF(bDesgaste="Por kg",$I18,1)+vLimpeza*IF(bLimpeza="Por kg",$I18,1)) | Z18: =IF($C18="","",U18+V18+W18+X18+Y18) | AA18: =IF($C18="","",H18+Z18) | AB18: =IF($C18="","",IFERROR(AA18/$I18,0)) | AC18: =IF($C18="","",$I18*O18) | AD18: =IF($C18="","",AC18-H18) | AE18: =IF($C18="","",AC18-AA18) | AF18: =IF($C18="","",IFERROR(AE18/AC18,0)) | AG18: =IF($C18="","",IFERROR(O18/AB18,0)) | AH18: =IF($C18="","",AB18) | AI18: =IF($C18="","",IFERROR(AB18/(1-IFERROR(INDEX(Prod_Margem,MATCH($C18,Prod_Nome,0)),0)),0)) | AJ18: =IF($C18="","",IFERROR(INDEX(Prod_Categoria,MATCH($C18,Prod_Nome,0)),"")) | AK18: =IF($C18="","",IFERROR(INDEX(Prod_Fornecedor,MATCH($C18,Prod_Nome,0)),"")) | AL18: =IF($A18="","",DATE(YEAR($A18),MONTH($A18),1))
D19: =IF($C19="","",IFERROR(INDEX(Prod_Marca,MATCH($C19,Prod_Nome,0)),"")) | H19: =IF($C19="","",$F19*$G19) | O19: =IF($C19="","",IFERROR(INDEX(Prod_PrecoVenda,MATCH($C19,Prod_Nome,0)),0)) | Q19: =IF($C19="","",$J19+$K19+$L19) | R19: =IF($C19="","",IFERROR((Q19)/$F19,0)) | S19: =IF($C19="","",(Q19)*$G19) | T19: =IF($C19="","",(Q19)*$G19) | U19: =IF($C19="","",vEmbalagem*IF(bEmbalagem="Por kg",$I19,1)) | V19: =IF($C19="","",vEtiqueta*IF(bEtiqueta="Por kg",$I19,1)) | W19: =IF($C19="","",vMaoObra*IF(bMaoObra="Por kg",$I19,1)) | X19: =IF($C19="","",vEnergia*IF(bEnergia="Por kg",$I19,1)) | Y19: =IF($C19="","",vFilme*IF(bFilme="Por kg",$I19,1)+vDesgaste*IF(bDesgaste="Por kg",$I19,1)+vLimpeza*IF(bLimpeza="Por kg",$I19,1)) | Z19: =IF($C19="","",U19+V19+W19+X19+Y19) | AA19: =IF($C19="","",H19+Z19) | AB19: =IF($C19="","",IFERROR(AA19/$I19,0)) | AC19: =IF($C19="","",$I19*O19) | AD19: =IF($C19="","",AC19-H19) | AE19: =IF($C19="","",AC19-AA19) | AF19: =IF($C19="","",IFERROR(AE19/AC19,0)) | AG19: =IF($C19="","",IFERROR(O19/AB19,0)) | AH19: =IF($C19="","",AB19) | AI19: =IF($C19="","",IFERROR(AB19/(1-IFERROR(INDEX(Prod_Margem,MATCH($C19,Prod_Nome,0)),0)),0)) | AJ19: =IF($C19="","",IFERROR(INDEX(Prod_Categoria,MATCH($C19,Prod_Nome,0)),"")) | AK19: =IF($C19="","",IFERROR(INDEX(Prod_Fornecedor,MATCH($C19,Prod_Nome,0)),"")) | AL19: =IF($A19="","",DATE(YEAR($A19),MONTH($A19),1))
D20: =IF($C20="","",IFERROR(INDEX(Prod_Marca,MATCH($C20,Prod_Nome,0)),"")) | H20: =IF($C20="","",$F20*$G20) | O20: =IF($C20="","",IFERROR(INDEX(Prod_PrecoVenda,MATCH($C20,Prod_Nome,0)),0)) | Q20: =IF($C20="","",$J20+$K20+$L20) | R20: =IF($C20="","",IFERROR((Q20)/$F20,0)) | S20: =IF($C20="","",(Q20)*$G20) | T20: =IF($C20="","",(Q20)*$G20) | U20: =IF($C20="","",vEmbalagem*IF(bEmbalagem="Por kg",$I20,1)) | V20: =IF($C20="","",vEtiqueta*IF(bEtiqueta="Por kg",$I20,1)) | W20: =IF($C20="","",vMaoObra*IF(bMaoObra="Por kg",$I20,1)) | X20: =IF($C20="","",vEnergia*IF(bEnergia="Por kg",$I20,1)) | Y20: =IF($C20="","",vFilme*IF(bFilme="Por kg",$I20,1)+vDesgaste*IF(bDesgaste="Por kg",$I20,1)+vLimpeza*IF(bLimpeza="Por kg",$I20,1)) | Z20: =IF($C20="","",U20+V20+W20+X20+Y20) | AA20: =IF($C20="","",H20+Z20) | AB20: =IF($C20="","",IFERROR(AA20/$I20,0)) | AC20: =IF($C20="","",$I20*O20) | AD20: =IF($C20="","",AC20-H20) | AE20: =IF($C20="","",AC20-AA20) | AF20: =IF($C20="","",IFERROR(AE20/AC20,0)) | AG20: =IF($C20="","",IFERROR(O20/AB20,0)) | AH20: =IF($C20="","",AB20) | AI20: =IF($C20="","",IFERROR(AB20/(1-IFERROR(INDEX(Prod_Margem,MATCH($C20,Prod_Nome,0)),0)),0)) | AJ20: =IF($C20="","",IFERROR(INDEX(Prod_Categoria,MATCH($C20,Prod_Nome,0)),"")) | AK20: =IF($C20="","",IFERROR(INDEX(Prod_Fornecedor,MATCH($C20,Prod_Nome,0)),"")) | AL20: =IF($A20="","",DATE(YEAR($A20),MONTH($A20),1))
D21: =IF($C21="","",IFERROR(INDEX(Prod_Marca,MATCH($C21,Prod_Nome,0)),"")) | H21: =IF($C21="","",$F21*$G21) | O21: =IF($C21="","",IFERROR(INDEX(Prod_PrecoVenda,MATCH($C21,Prod_Nome,0)),0)) | Q21: =IF($C21="","",$J21+$K21+$L21) | R21: =IF($C21="","",IFERROR((Q21)/$F21,0)) | S21: =IF($C21="","",(Q21)*$G21) | T21: =IF($C21="","",(Q21)*$G21) | U21: =IF($C21="","",vEmbalagem*IF(bEmbalagem="Por kg",$I21,1)) | V21: =IF($C21="","",vEtiqueta*IF(bEtiqueta="Por kg",$I21,1)) | W21: =IF($C21="","",vMaoObra*IF(bMaoObra="Por kg",$I21,1)) | X21: =IF($C21="","",vEnergia*IF(bEnergia="Por kg",$I21,1)) | Y21: =IF($C21="","",vFilme*IF(bFilme="Por kg",$I21,1)+vDesgaste*IF(bDesgaste="Por kg",$I21,1)+vLimpeza*IF(bLimpeza="Por kg",$I21,1)) | Z21: =IF($C21="","",U21+V21+W21+X21+Y21) | AA21: =IF($C21="","",H21+Z21) | AB21: =IF($C21="","",IFERROR(AA21/$I21,0)) | AC21: =IF($C21="","",$I21*O21) | AD21: =IF($C21="","",AC21-H21) | AE21: =IF($C21="","",AC21-AA21) | AF21: =IF($C21="","",IFERROR(AE21/AC21,0)) | AG21: =IF($C21="","",IFERROR(O21/AB21,0)) | AH21: =IF($C21="","",AB21) | AI21: =IF($C21="","",IFERROR(AB21/(1-IFERROR(INDEX(Prod_Margem,MATCH($C21,Prod_Nome,0)),0)),0)) | AJ21: =IF($C21="","",IFERROR(INDEX(Prod_Categoria,MATCH($C21,Prod_Nome,0)),"")) | AK21: =IF($C21="","",IFERROR(INDEX(Prod_Fornecedor,MATCH($C21,Prod_Nome,0)),"")) | AL21: =IF($A21="","",DATE(YEAR($A21),MONTH($A21),1))
D22: =IF($C22="","",IFERROR(INDEX(Prod_Marca,MATCH($C22,Prod_Nome,0)),"")) | H22: =IF($C22="","",$F22*$G22) | O22: =IF($C22="","",IFERROR(INDEX(Prod_PrecoVenda,MATCH($C22,Prod_Nome,0)),0)) | Q22: =IF($C22="","",$J22+$K22+$L22) | R22: =IF($C22="","",IFERROR((Q22)/$F22,0)) | S22: =IF($C22="","",(Q22)*$G22) | T22: =IF($C22="","",(Q22)*$G22) | U22: =IF($C22="","",vEmbalagem*IF(bEmbalagem="Por kg",$I22,1)) | V22: =IF($C22="","",vEtiqueta*IF(bEtiqueta="Por kg",$I22,1)) | W22: =IF($C22="","",vMaoObra*IF(bMaoObra="Por kg",$I22,1)) | X22: =IF($C22="","",vEnergia*IF(bEnergia="Por kg",$I22,1)) | Y22: =IF($C22="","",vFilme*IF(bFilme="Por kg",$I22,1)+vDesgaste*IF(bDesgaste="Por kg",$I22,1)+vLimpeza*IF(bLimpeza="Por kg",$I22,1)) | Z22: =IF($C22="","",U22+V22+W22+X22+Y22) | AA22: =IF($C22="","",H22+Z22) | AB22: =IF($C22="","",IFERROR(AA22/$I22,0)) | AC22: =IF($C22="","",$I22*O22) | AD22: =IF($C22="","",AC22-H22) | AE22: =IF($C22="","",AC22-AA22) | AF22: =IF($C22="","",IFERROR(AE22/AC22,0)) | AG22: =IF($C22="","",IFERROR(O22/AB22,0)) | AH22: =IF($C22="","",AB22) | AI22: =IF($C22="","",IFERROR(AB22/(1-IFERROR(INDEX(Prod_Margem,MATCH($C22,Prod_Nome,0)),0)),0)) | AJ22: =IF($C22="","",IFERROR(INDEX(Prod_Categoria,MATCH($C22,Prod_Nome,0)),"")) | AK22: =IF($C22="","",IFERROR(INDEX(Prod_Fornecedor,MATCH($C22,Prod_Nome,0)),"")) | AL22: =IF($A22="","",DATE(YEAR($A22),MONTH($A22),1))
D23: =IF($C23="","",IFERROR(INDEX(Prod_Marca,MATCH($C23,Prod_Nome,0)),"")) | H23: =IF($C23="","",$F23*$G23) | O23: =IF($C23="","",IFERROR(INDEX(Prod_PrecoVenda,MATCH($C23,Prod_Nome,0)),0)) | Q23: =IF($C23="","",$J23+$K23+$L23) | R23: =IF($C23="","",IFERROR((Q23)/$F23,0)) | S23: =IF($C23="","",(Q23)*$G23) | T23: =IF($C23="","",(Q23)*$G23) | U23: =IF($C23="","",vEmbalagem*IF(bEmbalagem="Por kg",$I23,1)) | V23: =IF($C23="","",vEtiqueta*IF(bEtiqueta="Por kg",$I23,1)) | W23: =IF($C23="","",vMaoObra*IF(bMaoObra="Por kg",$I23,1)) | X23: =IF($C23="","",vEnergia*IF(bEnergia="Por kg",$I23,1)) | Y23: =IF($C23="","",vFilme*IF(bFilme="Por kg",$I23,1)+vDesgaste*IF(bDesgaste="Por kg",$I23,1)+vLimpeza*IF(bLimpeza="Por kg",$I23,1)) | Z23: =IF($C23="","",U23+V23+W23+X23+Y23) | AA23: =IF($C23="","",H23+Z23) | AB23: =IF($C23="","",IFERROR(AA23/$I23,0)) | AC23: =IF($C23="","",$I23*O23) | AD23: =IF($C23="","",AC23-H23) | AE23: =IF($C23="","",AC23-AA23) | AF23: =IF($C23="","",IFERROR(AE23/AC23,0)) | AG23: =IF($C23="","",IFERROR(O23/AB23,0)) | AH23: =IF($C23="","",AB23) | AI23: =IF($C23="","",IFERROR(AB23/(1-IFERROR(INDEX(Prod_Margem,MATCH($C23,Prod_Nome,0)),0)),0)) | AJ23: =IF($C23="","",IFERROR(INDEX(Prod_Categoria,MATCH($C23,Prod_Nome,0)),"")) | AK23: =IF($C23="","",IFERROR(INDEX(Prod_Fornecedor,MATCH($C23,Prod_Nome,0)),"")) | AL23: =IF($A23="","",DATE(YEAR($A23),MONTH($A23),1))
D24: =IF($C24="","",IFERROR(INDEX(Prod_Marca,MATCH($C24,Prod_Nome,0)),"")) | H24: =IF($C24="","",$F24*$G24) | O24: =IF($C24="","",IFERROR(INDEX(Prod_PrecoVenda,MATCH($C24,Prod_Nome,0)),0)) | Q24: =IF($C24="","",$J24+$K24+$L24) | R24: =IF($C24="","",IFERROR((Q24)/$F24,0)) | S24: =IF($C24="","",(Q24)*$G24) | T24: =IF($C24="","",(Q24)*$G24) | U24: =IF($C24="","",vEmbalagem*IF(bEmbalagem="Por kg",$I24,1)) | V24: =IF($C24="","",vEtiqueta*IF(bEtiqueta="Por kg",$I24,1)) | W24: =IF($C24="","",vMaoObra*IF(bMaoObra="Por kg",$I24,1)) | X24: =IF($C24="","",vEnergia*IF(bEnergia="Por kg",$I24,1)) | Y24: =IF($C24="","",vFilme*IF(bFilme="Por kg",$I24,1)+vDesgaste*IF(bDesgaste="Por kg",$I24,1)+vLimpeza*IF(bLimpeza="Por kg",$I24,1)) | Z24: =IF($C24="","",U24+V24+W24+X24+Y24) | AA24: =IF($C24="","",H24+Z24) | AB24: =IF($C24="","",IFERROR(AA24/$I24,0)) | AC24: =IF($C24="","",$I24*O24) | AD24: =IF($C24="","",AC24-H24) | AE24: =IF($C24="","",AC24-AA24) | AF24: =IF($C24="","",IFERROR(AE24/AC24,0)) | AG24: =IF($C24="","",IFERROR(O24/AB24,0)) | AH24: =IF($C24="","",AB24) | AI24: =IF($C24="","",IFERROR(AB24/(1-IFERROR(INDEX(Prod_Margem,MATCH($C24,Prod_Nome,0)),0)),0)) | AJ24: =IF($C24="","",IFERROR(INDEX(Prod_Categoria,MATCH($C24,Prod_Nome,0)),"")) | AK24: =IF($C24="","",IFERROR(INDEX(Prod_Fornecedor,MATCH($C24,Prod_Nome,0)),"")) | AL24: =IF($A24="","",DATE(YEAR($A24),MONTH($A24),1))
D25: =IF($C25="","",IFERROR(INDEX(Prod_Marca,MATCH($C25,Prod_Nome,0)),"")) | H25: =IF($C25="","",$F25*$G25) | O25: =IF($C25="","",IFERROR(INDEX(Prod_PrecoVenda,MATCH($C25,Prod_Nome,0)),0)) | Q25: =IF($C25="","",$J25+$K25+$L25) | R25: =IF($C25="","",IFERROR((Q25)/$F25,0)) | S25: =IF($C25="","",(Q25)*$G25) | T25: =IF($C25="","",(Q25)*$G25) | U25: =IF($C25="","",vEmbalagem*IF(bEmbalagem="Por kg",$I25,1)) | V25: =IF($C25="","",vEtiqueta*IF(bEtiqueta="Por kg",$I25,1)) | W25: =IF($C25="","",vMaoObra*IF(bMaoObra="Por kg",$I25,1)) | X25: =IF($C25="","",vEnergia*IF(bEnergia="Por kg",$I25,1)) | Y25: =IF($C25="","",vFilme*IF(bFilme="Por kg",$I25,1)+vDesgaste*IF(bDesgaste="Por kg",$I25,1)+vLimpeza*IF(bLimpeza="Por kg",$I25,1)) | Z25: =IF($C25="","",U25+V25+W25+X25+Y25) | AA25: =IF($C25="","",H25+Z25) | AB25: =IF($C25="","",IFERROR(AA25/$I25,0)) | AC25: =IF($C25="","",$I25*O25) | AD25: =IF($C25="","",AC25-H25) | AE25: =IF($C25="","",AC25-AA25) | AF25: =IF($C25="","",IFERROR(AE25/AC25,0)) | AG25: =IF($C25="","",IFERROR(O25/AB25,0)) | AH25: =IF($C25="","",AB25) | AI25: =IF($C25="","",IFERROR(AB25/(1-IFERROR(INDEX(Prod_Margem,MATCH($C25,Prod_Nome,0)),0)),0)) | AJ25: =IF($C25="","",IFERROR(INDEX(Prod_Categoria,MATCH($C25,Prod_Nome,0)),"")) | AK25: =IF($C25="","",IFERROR(INDEX(Prod_Fornecedor,MATCH($C25,Prod_Nome,0)),"")) | AL25: =IF($A25="","",DATE(YEAR($A25),MONTH($A25),1))
D26: =IF($C26="","",IFERROR(INDEX(Prod_Marca,MATCH($C26,Prod_Nome,0)),"")) | H26: =IF($C26="","",$F26*$G26) | O26: =IF($C26="","",IFERROR(INDEX(Prod_PrecoVenda,MATCH($C26,Prod_Nome,0)),0)) | Q26: =IF($C26="","",$J26+$K26+$L26) | R26: =IF($C26="","",IFERROR((Q26)/$F26,0)) | S26: =IF($C26="","",(Q26)*$G26) | T26: =IF($C26="","",(Q26)*$G26) | U26: =IF($C26="","",vEmbalagem*IF(bEmbalagem="Por kg",$I26,1)) | V26: =IF($C26="","",vEtiqueta*IF(bEtiqueta="Por kg",$I26,1)) | W26: =IF($C26="","",vMaoObra*IF(bMaoObra="Por kg",$I26,1)) | X26: =IF($C26="","",vEnergia*IF(bEnergia="Por kg",$I26,1)) | Y26: =IF($C26="","",vFilme*IF(bFilme="Por kg",$I26,1)+vDesgaste*IF(bDesgaste="Por kg",$I26,1)+vLimpeza*IF(bLimpeza="Por kg",$I26,1)) | Z26: =IF($C26="","",U26+V26+W26+X26+Y26) | AA26: =IF($C26="","",H26+Z26) | AB26: =IF($C26="","",IFERROR(AA26/$I26,0)) | AC26: =IF($C26="","",$I26*O26) | AD26: =IF($C26="","",AC26-H26) | AE26: =IF($C26="","",AC26-AA26) | AF26: =IF($C26="","",IFERROR(AE26/AC26,0)) | AG26: =IF($C26="","",IFERROR(O26/AB26,0)) | AH26: =IF($C26="","",AB26) | AI26: =IF($C26="","",IFERROR(AB26/(1-IFERROR(INDEX(Prod_Margem,MATCH($C26,Prod_Nome,0)),0)),0)) | AJ26: =IF($C26="","",IFERROR(INDEX(Prod_Categoria,MATCH($C26,Prod_Nome,0)),"")) | AK26: =IF($C26="","",IFERROR(INDEX(Prod_Fornecedor,MATCH($C26,Prod_Nome,0)),"")) | AL26: =IF($A26="","",DATE(YEAR($A26),MONTH($A26),1))
D27: =IF($C27="","",IFERROR(INDEX(Prod_Marca,MATCH($C27,Prod_Nome,0)),"")) | H27: =IF($C27="","",$F27*$G27) | O27: =IF($C27="","",IFERROR(INDEX(Prod_PrecoVenda,MATCH($C27,Prod_Nome,0)),0)) | Q27: =IF($C27="","",$J27+$K27+$L27) | R27: =IF($C27="","",IFERROR((Q27)/$F27,0)) | S27: =IF($C27="","",(Q27)*$G27) | T27: =IF($C27="","",(Q27)*$G27) | U27: =IF($C27="","",vEmbalagem*IF(bEmbalagem="Por kg",$I27,1)) | V27: =IF($C27="","",vEtiqueta*IF(bEtiqueta="Por kg",$I27,1)) | W27: =IF($C27="","",vMaoObra*IF(bMaoObra="Por kg",$I27,1)) | X27: =IF($C27="","",vEnergia*IF(bEnergia="Por kg",$I27,1)) | Y27: =IF($C27="","",vFilme*IF(bFilme="Por kg",$I27,1)+vDesgaste*IF(bDesgaste="Por kg",$I27,1)+vLimpeza*IF(bLimpeza="Por kg",$I27,1)) | Z27: =IF($C27="","",U27+V27+W27+X27+Y27) | AA27: =IF($C27="","",H27+Z27) | AB27: =IF($C27="","",IFERROR(AA27/$I27,0)) | AC27: =IF($C27="","",$I27*O27) | AD27: =IF($C27="","",AC27-H27) | AE27: =IF($C27="","",AC27-AA27) | AF27: =IF($C27="","",IFERROR(AE27/AC27,0)) | AG27: =IF($C27="","",IFERROR(O27/AB27,0)) | AH27: =IF($C27="","",AB27) | AI27: =IF($C27="","",IFERROR(AB27/(1-IFERROR(INDEX(Prod_Margem,MATCH($C27,Prod_Nome,0)),0)),0)) | AJ27: =IF($C27="","",IFERROR(INDEX(Prod_Categoria,MATCH($C27,Prod_Nome,0)),"")) | AK27: =IF($C27="","",IFERROR(INDEX(Prod_Fornecedor,MATCH($C27,Prod_Nome,0)),"")) | AL27: =IF($A27="","",DATE(YEAR($A27),MONTH($A27),1))
D28: =IF($C28="","",IFERROR(INDEX(Prod_Marca,MATCH($C28,Prod_Nome,0)),"")) | H28: =IF($C28="","",$F28*$G28) | O28: =IF($C28="","",IFERROR(INDEX(Prod_PrecoVenda,MATCH($C28,Prod_Nome,0)),0)) | Q28: =IF($C28="","",$J28+$K28+$L28) | R28: =IF($C28="","",IFERROR((Q28)/$F28,0)) | S28: =IF($C28="","",(Q28)*$G28) | T28: =IF($C28="","",(Q28)*$G28) | U28: =IF($C28="","",vEmbalagem*IF(bEmbalagem="Por kg",$I28,1)) | V28: =IF($C28="","",vEtiqueta*IF(bEtiqueta="Por kg",$I28,1)) | W28: =IF($C28="","",vMaoObra*IF(bMaoObra="Por kg",$I28,1)) | X28: =IF($C28="","",vEnergia*IF(bEnergia="Por kg",$I28,1)) | Y28: =IF($C28="","",vFilme*IF(bFilme="Por kg",$I28,1)+vDesgaste*IF(bDesgaste="Por kg",$I28,1)+vLimpeza*IF(bLimpeza="Por kg",$I28,1)) | Z28: =IF($C28="","",U28+V28+W28+X28+Y28) | AA28: =IF($C28="","",H28+Z28) | AB28: =IF($C28="","",IFERROR(AA28/$I28,0)) | AC28: =IF($C28="","",$I28*O28) | AD28: =IF($C28="","",AC28-H28) | AE28: =IF($C28="","",AC28-AA28) | AF28: =IF($C28="","",IFERROR(AE28/AC28,0)) | AG28: =IF($C28="","",IFERROR(O28/AB28,0)) | AH28: =IF($C28="","",AB28) | AI28: =IF($C28="","",IFERROR(AB28/(1-IFERROR(INDEX(Prod_Margem,MATCH($C28,Prod_Nome,0)),0)),0)) | AJ28: =IF($C28="","",IFERROR(INDEX(Prod_Categoria,MATCH($C28,Prod_Nome,0)),"")) | AK28: =IF($C28="","",IFERROR(INDEX(Prod_Fornecedor,MATCH($C28,Prod_Nome,0)),"")) | AL28: =IF($A28="","",DATE(YEAR($A28),MONTH($A28),1))
D29: =IF($C29="","",IFERROR(INDEX(Prod_Marca,MATCH($C29,Prod_Nome,0)),"")) | H29: =IF($C29="","",$F29*$G29) | O29: =IF($C29="","",IFERROR(INDEX(Prod_PrecoVenda,MATCH($C29,Prod_Nome,0)),0)) | Q29: =IF($C29="","",$J29+$K29+$L29) | R29: =IF($C29="","",IFERROR((Q29)/$F29,0)) | S29: =IF($C29="","",(Q29)*$G29) | T29: =IF($C29="","",(Q29)*$G29) | U29: =IF($C29="","",vEmbalagem*IF(bEmbalagem="Por kg",$I29,1)) | V29: =IF($C29="","",vEtiqueta*IF(bEtiqueta="Por kg",$I29,1)) | W29: =IF($C29="","",vMaoObra*IF(bMaoObra="Por kg",$I29,1)) | X29: =IF($C29="","",vEnergia*IF(bEnergia="Por kg",$I29,1)) | Y29: =IF($C29="","",vFilme*IF(bFilme="Por kg",$I29,1)+vDesgaste*IF(bDesgaste="Por kg",$I29,1)+vLimpeza*IF(bLimpeza="Por kg",$I29,1)) | Z29: =IF($C29="","",U29+V29+W29+X29+Y29) | AA29: =IF($C29="","",H29+Z29) | AB29: =IF($C29="","",IFERROR(AA29/$I29,0)) | AC29: =IF($C29="","",$I29*O29) | AD29: =IF($C29="","",AC29-H29) | AE29: =IF($C29="","",AC29-AA29) | AF29: =IF($C29="","",IFERROR(AE29/AC29,0)) | AG29: =IF($C29="","",IFERROR(O29/AB29,0)) | AH29: =IF($C29="","",AB29) | AI29: =IF($C29="","",IFERROR(AB29/(1-IFERROR(INDEX(Prod_Margem,MATCH($C29,Prod_Nome,0)),0)),0)) | AJ29: =IF($C29="","",IFERROR(INDEX(Prod_Categoria,MATCH($C29,Prod_Nome,0)),"")) | AK29: =IF($C29="","",IFERROR(INDEX(Prod_Fornecedor,MATCH($C29,Prod_Nome,0)),"")) | AL29: =IF($A29="","",DATE(YEAR($A29),MONTH($A29),1))
D30: =IF($C30="","",IFERROR(INDEX(Prod_Marca,MATCH($C30,Prod_Nome,0)),"")) | H30: =IF($C30="","",$F30*$G30) | O30: =IF($C30="","",IFERROR(INDEX(Prod_PrecoVenda,MATCH($C30,Prod_Nome,0)),0)) | Q30: =IF($C30="","",$J30+$K30+$L30) | R30: =IF($C30="","",IFERROR((Q30)/$F30,0)) | S30: =IF($C30="","",(Q30)*$G30) | T30: =IF($C30="","",(Q30)*$G30) | U30: =IF($C30="","",vEmbalagem*IF(bEmbalagem="Por kg",$I30,1)) | V30: =IF($C30="","",vEtiqueta*IF(bEtiqueta="Por kg",$I30,1)) | W30: =IF($C30="","",vMaoObra*IF(bMaoObra="Por kg",$I30,1)) | X30: =IF($C30="","",vEnergia*IF(bEnergia="Por kg",$I30,1)) | Y30: =IF($C30="","",vFilme*IF(bFilme="Por kg",$I30,1)+vDesgaste*IF(bDesgaste="Por kg",$I30,1)+vLimpeza*IF(bLimpeza="Por kg",$I30,1)) | Z30: =IF($C30="","",U30+V30+W30+X30+Y30) | AA30: =IF($C30="","",H30+Z30) | AB30: =IF($C30="","",IFERROR(AA30/$I30,0)) | AC30: =IF($C30="","",$I30*O30) | AD30: =IF($C30="","",AC30-H30) | AE30: =IF($C30="","",AC30-AA30) | AF30: =IF($C30="","",IFERROR(AE30/AC30,0)) | AG30: =IF($C30="","",IFERROR(O30/AB30,0)) | AH30: =IF($C30="","",AB30) | AI30: =IF($C30="","",IFERROR(AB30/(1-IFERROR(INDEX(Prod_Margem,MATCH($C30,Prod_Nome,0)),0)),0)) | AJ30: =IF($C30="","",IFERROR(INDEX(Prod_Categoria,MATCH($C30,Prod_Nome,0)),"")) | AK30: =IF($C30="","",IFERROR(INDEX(Prod_Fornecedor,MATCH($C30,Prod_Nome,0)),"")) | AL30: =IF($A30="","",DATE(YEAR($A30),MONTH($A30),1))
... D64: =IF($C64="","",IFERROR(INDEX(Prod_Marca,MATCH($C64,Prod_Nome,0)),"")) | H64: =IF($C64="","",$F64*$G64) | O64: =IF($C64="","",IFERROR(INDEX(Prod_PrecoVenda,MATCH($C64,Prod_Nome,0)),0)) | Q64: =IF($C64="","",$J64+$K64+$L64) | R64: =IF($C64="","",IFERROR((Q64)/$F64,0)) | S64: =IF($C64="","",(Q64)*$G64) | T64: =IF($C64="","",(Q64)*$G64) | U64: =IF($C64="","",vEmbalagem*IF(bEmbalagem="Por kg",$I64,1)) | V64: =IF($C64="","",vEtiqueta*IF(bEtiqueta="Por kg",$I64,1)) | W64: =IF($C64="","",vMaoObra*IF(bMaoObra="Por kg",$I64,1)) | X64: =IF($C64="","",vEnergia*IF(bEnergia="Por kg",$I64,1)) | Y64: =IF($C64="","",vFilme*IF(bFilme="Por kg",$I64,1)+vDesgaste*IF(bDesgaste="Por kg",$I64,1)+vLimpeza*IF(bLimpeza="Por kg",$I64,1)) | Z64: =IF($C64="","",U64+V64+W64+X64+Y64) | AA64: =IF($C64="","",H64+Z64) | AB64: =IF($C64="","",IFERROR(AA64/$I64,0)) | AC64: =IF($C64="","",$I64*O64) | AD64: =IF($C64="","",AC64-H64) | AE64: =IF($C64="","",AC64-AA64) | AF64: =IF($C64="","",IFERROR(AE64/AC64,0)) | AG64: =IF($C64="","",IFERROR(O64/AB64,0)) | AH64: =IF($C64="","",AB64) | AI64: =IF($C64="","",IFERROR(AB64/(1-IFERROR(INDEX(Prod_Margem,MATCH($C64,Prod_Nome,0)),0)),0)) | AJ64: =IF($C64="","",IFERROR(INDEX(Prod_Categoria,MATCH($C64,Prod_Nome,0)),"")) | AK64: =IF($C64="","",IFERROR(INDEX(Prod_Fornecedor,MATCH($C64,Prod_Nome,0)),"")) | AL64: =IF($A64="","",DATE(YEAR($A64),MONTH($A64),1))

Sheet Dashboard
A1: DASHBOARD DE GESTAO - ED FRIOS
A2: Visao geral da operacao de fatiamento. Atualiza automaticamente conforme os lancamentos.
A3: Inicio | B3: Produtos | C3: Custos | D3: Fatiamento | E3: Dashboard | F3: Relatorios
A5: PECAS ABERTAS | C5: KG COMPRADOS | E5: KG VENDIDOS | G5: SEMAFORO DE DESEMPENHO
A6: =SUMPRODUCT(--(Fat_Produto<>"")) | C6: =SUM(Fat_PesoAntes) | E6: =SUM(Fat_PesoVend) | G6: =IF(E9>MetaPerdaMax,"CRITICO",IF(E9>MetaPerda,"ATENCAO","SAUDAVEL"))
A8: KG PERDIDOS | C8: VALOR PERDIDO | E8: PERDA MEDIA | G8: Produto + lucrativo | I8: Funcionario + perda
A9: =SUM(Fat_PesoPerd) | C9: =SUM(Fat_ValorPerd) | E9: =IFERROR(SUM(Fat_PesoPerd)/SUM(Fat_PesoAntes),0) | G9: =IFERROR(INDEX(Base_Prod,MATCH(MAX(Base_KeyLucro),Base_KeyLucro,0)),"-") | I9: =IFERROR(INDEX(Base_Func,MATCH(MAX(Base_FuncPerdaPct),Base_FuncPerdaPct,0)),"-")
A11: LUCRO BRUTO | C11: LUCRO LIQUIDO | E11: MARGEM MEDIA | G11: Produto + desperdicio | I11: Fornecedor + perda
A12: =SUM(Fat_LucroBruto) | C12: =SUM(Fat_LucroLiq) | E12: =IFERROR(SUM(Fat_LucroLiq)/SUM(Fat_Receita),0) | G12: =IFERROR(INDEX(Base_Prod,MATCH(MAX(Base_KeyPerda),Base_KeyPerda,0)),"-") | I12: =IFERROR(INDEX(Base_Forn,MATCH(MAX(Base_FornValor),Base_FornValor,0)),"-")
A15: RANKING - MAIOR PERDA (R$) | E15: RANKING - MAIOR LUCRO (R$) | I15: RANKING - FUNCIONARIOS (% perda)
A16: # | B16: Produto | C16: Valor perdido | E16: # | F16: Produto | G16: Lucro liquido | I16: # | J16: Funcionario | K16: % perda
A17: 1 | B17: =IFERROR(INDEX(Base_Prod,MATCH(LARGE(Base_KeyPerda,1),Base_KeyPerda,0)),"-") | C17: =IFERROR(INDEX(Base_ValorPerd,MATCH(LARGE(Base_KeyPerda,1),Base_KeyPerda,0)),0) | E17: 1 | F17: =IFERROR(INDEX(Base_Prod,MATCH(LARGE(Base_KeyLucro,1),Base_KeyLucro,0)),"-") | G17: =IFERROR(INDEX(Base_Lucro,MATCH(LARGE(Base_KeyLucro,1),Base_KeyLucro,0)),0) | I17: 1 | J17: =IFERROR(INDEX(Base_Func,MATCH(LARGE(Base_FuncPerdaPct,1),Base_FuncPerdaPct,0)),"-") | K17: =IFERROR(LARGE(Base_FuncPerdaPct,1),0)
A18: 2 | B18: =IFERROR(INDEX(Base_Prod,MATCH(LARGE(Base_KeyPerda,2),Base_KeyPerda,0)),"-") | C18: =IFERROR(INDEX(Base_ValorPerd,MATCH(LARGE(Base_KeyPerda,2),Base_KeyPerda,0)),0) | E18: 2 | F18: =IFERROR(INDEX(Base_Prod,MATCH(LARGE(Base_KeyLucro,2),Base_KeyLucro,0)),"-") | G18: =IFERROR(INDEX(Base_Lucro,MATCH(LARGE(Base_KeyLucro,2),Base_KeyLucro,0)),0) | I18: 2 | J18: =IFERROR(INDEX(Base_Func,MATCH(LARGE(Base_FuncPerdaPct,2),Base_FuncPerdaPct,0)),"-") | K18: =IFERROR(LARGE(Base_FuncPerdaPct,2),0)
A19: 3 | B19: =IFERROR(INDEX(Base_Prod,MATCH(LARGE(Base_KeyPerda,3),Base_KeyPerda,0)),"-") | C19: =IFERROR(INDEX(Base_ValorPerd,MATCH(LARGE(Base_KeyPerda,3),Base_KeyPerda,0)),0) | E19: 3 | F19: =IFERROR(INDEX(Base_Prod,MATCH(LARGE(Base_KeyLucro,3),Base_KeyLucro,0)),"-") | G19: =IFERROR(INDEX(Base_Lucro,MATCH(LARGE(Base_KeyLucro,3),Base_KeyLucro,0)),0) | I19: 3 | J19: =IFERROR(INDEX(Base_Func,MATCH(LARGE(Base_FuncPerdaPct,3),Base_FuncPerdaPct,0)),"-") | K19: =IFERROR(LARGE(Base_FuncPerdaPct,3),0)
A20: 4 | B20: =IFERROR(INDEX(Base_Prod,MATCH(LARGE(Base_KeyPerda,4),Base_KeyPerda,0)),"-") | C20: =IFERROR(INDEX(Base_ValorPerd,MATCH(LARGE(Base_KeyPerda,4),Base_KeyPerda,0)),0) | E20: 4 | F20: =IFERROR(INDEX(Base_Prod,MATCH(LARGE(Base_KeyLucro,4),Base_KeyLucro,0)),"-") | G20: =IFERROR(INDEX(Base_Lucro,MATCH(LARGE(Base_KeyLucro,4),Base_KeyLucro,0)),0) | I20: 4 | J20: =IFERROR(INDEX(Base_Func,MATCH(LARGE(Base_FuncPerdaPct,4),Base_FuncPerdaPct,0)),"-") | K20: =IFERROR(LARGE(Base_FuncPerdaPct,4),0)
A21: 5 | B21: =IFERROR(INDEX(Base_Prod,MATCH(LARGE(Base_KeyPerda,5),Base_KeyPerda,0)),"-") | C21: =IFERROR(INDEX(Base_ValorPerd,MATCH(LARGE(Base_KeyPerda,5),Base_KeyPerda,0)),0) | E21: 5 | F21: =IFERROR(INDEX(Base_Prod,MATCH(LARGE(Base_KeyLucro,5),Base_KeyLucro,0)),"-") | G21: =IFERROR(INDEX(Base_Lucro,MATCH(LARGE(Base_KeyLucro,5),Base_KeyLucro,0)),0) | I21: 5 | J21: =IFERROR(INDEX(Base_Func,MATCH(LARGE(Base_FuncPerdaPct,5),Base_FuncPerdaPct,0)),"-") | K21: =IFERROR(LARGE(Base_FuncPerdaPct,5),0)

Sheet Relatorios
A1: RELATORIOS FILTRAVEIS
A2: Escolha os filtros (deixe em branco para 'todos'). Os totais recalculam sozinhos.
A3: Inicio | B3: Produtos | C3: Custos | D3: Fatiamento | E3: Dashboard | F3: Relatorios
A5: FILTROS
A6: Produto | E6: =IF($B6="","*",$B6)
A7: Fornecedor | E7: =IF($B7="","*",$B7)
A8: Funcionario | E8: =IF($B8="","*",$B8)
A9: Marca | E9: =IF($B9="","*",$B9)
A10: Categoria | E10: =IF($B10="","*",$B10)
A11: Data inicio | E11: =IF($B11="",DATE(1900,1,1),$B11)
A12: Data fim | E12: =IF($B12="",DATE(2100,12,31),$B12)
A15: RESULTADO DO PERIODO/FILTRO
A16: Total comprado (kg) | B16: =SUMIFS(Fat_PesoAntes,Fat_Produto,$E$6,Fat_Fornecedor,$E$7,Fat_Func,$E$8,Fat_Marca,$E$9,Fat_Categoria,$E$10,Fat_Data,">="&$E$11,Fat_Data,"<="&$E$12)
A17: Total vendido (kg) | B17: =SUMIFS(Fat_PesoVend,Fat_Produto,$E$6,Fat_Fornecedor,$E$7,Fat_Func,$E$8,Fat_Marca,$E$9,Fat_Categoria,$E$10,Fat_Data,">="&$E$11,Fat_Data,"<="&$E$12)
A18: Total perdido (kg) | B18: =SUMIFS(Fat_PesoPerd,Fat_Produto,$E$6,Fat_Fornecedor,$E$7,Fat_Func,$E$8,Fat_Marca,$E$9,Fat_Categoria,$E$10,Fat_Data,">="&$E$11,Fat_Data,"<="&$E$12)
A19: Valor perdido (R$) | B19: =SUMIFS(Fat_ValorPerd,Fat_Produto,$E$6,Fat_Fornecedor,$E$7,Fat_Func,$E$8,Fat_Marca,$E$9,Fat_Categoria,$E$10,Fat_Data,">="&$E$11,Fat_Data,"<="&$E$12)
A20: Receita (R$) | B20: =SUMIFS(Fat_Receita,Fat_Produto,$E$6,Fat_Fornecedor,$E$7,Fat_Func,$E$8,Fat_Marca,$E$9,Fat_Categoria,$E$10,Fat_Data,">="&$E$11,Fat_Data,"<="&$E$12)
A21: Lucro liquido (R$) | B21: =SUMIFS(Fat_LucroLiq,Fat_Produto,$E$6,Fat_Fornecedor,$E$7,Fat_Func,$E$8,Fat_Marca,$E$9,Fat_Categoria,$E$10,Fat_Data,">="&$E$11,Fat_Data,"<="&$E$12)
A22: Margem (%) | B22: =IFERROR(B21/B20,0)
A23: % perda | B23: =IFERROR(B18/B16,0)

Sheet Base Aux
A1: BASE AUXILIAR (calculos do dashboard - nao editar)
A3: POR PRODUTO | N3: POR FUNCIONARIO | T3: POR FORNECEDOR | Z3: POR MES
A4: Produto | B4: Kg comprado | C4: Kg vendido | D4: Kg perdido | E4: Valor perdido | F4: Receita | G4: Lucro liquido | H4: % perda | I4: Margem | J4: rank_perda | K4: rank_lucro | L4: Alerta | N4: Funcionario | O4: Kg comprado | P4: Kg perdido | Q4: Valor perdido | R4: % perda | T4: Fornecedor | U4: Kg comprado | V4: Kg perdido | W4: Valor perdido | X4: % perda | Z4: Mes | AA4: Kg vendido | AB4: Kg perdido | AC4: Valor perdido | AD4: Lucro liquido
A5: =IF('Cadastro Produtos'!$B5="","",'Cadastro Produtos'!$B5) | B5: =IF($A5="","",SUMIFS(Fat_PesoAntes,Fat_Produto,$A5)) | C5: =IF($A5="","",SUMIFS(Fat_PesoVend,Fat_Produto,$A5)) | D5: =IF($A5="","",SUMIFS(Fat_PesoPerd,Fat_Produto,$A5)) | E5: =IF($A5="","",SUMIFS(Fat_ValorPerd,Fat_Produto,$A5)) | F5: =IF($A5="","",SUMIFS(Fat_Receita,Fat_Produto,$A5)) | G5: =IF($A5="","",SUMIFS(Fat_LucroLiq,Fat_Produto,$A5)) | H5: =IF($A5="","",IFERROR($D5/$B5,0)) | I5: =IF($A5="","",IFERROR($G5/$F5,0)) | J5: =IF($A5="","",$E5+ROW()/1000000) | K5: =IF($A5="","",$G5+ROW()/1000000) | L5: =IF($A5="","",IF($H5>MetaPerdaMax,"ALERTA","OK")) | N5: Joao | O5: =SUMIFS(Fat_PesoAntes,Fat_Func,$N5) | P5: =SUMIFS(Fat_PesoPerd,Fat_Func,$N5) | Q5: =SUMIFS(Fat_ValorPerd,Fat_Func,$N5) | R5: =IFERROR($P5/$O5,0) | T5: Distribuidora A | U5: =SUMIFS(Fat_PesoAntes,Fat_Fornecedor,$T5) | V5: =SUMIFS(Fat_PesoPerd,Fat_Fornecedor,$T5) | W5: =SUMIFS(Fat_ValorPerd,Fat_Fornecedor,$T5) | X5: =IFERROR($V5/$U5,0) | Z5: 46023 | AA5: =SUMIFS(Fat_PesoVend,Fat_Mes,$Z5) | AB5: =SUMIFS(Fat_PesoPerd,Fat_Mes,$Z5) | AC5: =SUMIFS(Fat_ValorPerd,Fat_Mes,$Z5) | AD5: =SUMIFS(Fat_LucroLiq,Fat_Mes,$Z5)
A6: =IF('Cadastro Produtos'!$B6="","",'Cadastro Produtos'!$B6) | B6: =IF($A6="","",SUMIFS(Fat_PesoAntes,Fat_Produto,$A6)) | C6: =IF($A6="","",SUMIFS(Fat_PesoVend,Fat_Produto,$A6)) | D6: =IF($A6="","",SUMIFS(Fat_PesoPerd,Fat_Produto,$A6)) | E6: =IF($A6="","",SUMIFS(Fat_ValorPerd,Fat_Produto,$A6)) | F6: =IF($A6="","",SUMIFS(Fat_Receita,Fat_Produto,$A6)) | G6: =IF($A6="","",SUMIFS(Fat_LucroLiq,Fat_Produto,$A6)) | H6: =IF($A6="","",IFERROR($D6/$B6,0)) | I6: =IF($A6="","",IFERROR($G6/$F6,0)) | J6: =IF($A6="","",$E6+ROW()/1000000) | K6: =IF($A6="","",$G6+ROW()/1000000) | L6: =IF($A6="","",IF($H6>MetaPerdaMax,"ALERTA","OK")) | N6: Maria | O6: =SUMIFS(Fat_PesoAntes,Fat_Func,$N6) | P6: =SUMIFS(Fat_PesoPerd,Fat_Func,$N6) | Q6: =SUMIFS(Fat_ValorPerd,Fat_Func,$N6) | R6: =IFERROR($P6/$O6,0) | T6: Distribuidora B | U6: =SUMIFS(Fat_PesoAntes,Fat_Fornecedor,$T6) | V6: =SUMIFS(Fat_PesoPerd,Fat_Fornecedor,$T6) | W6: =SUMIFS(Fat_ValorPerd,Fat_Fornecedor,$T6) | X6: =IFERROR($V6/$U6,0) | Z6: 46054 | AA6: =SUMIFS(Fat_PesoVend,Fat_Mes,$Z6) | AB6: =SUMIFS(Fat_PesoPerd,Fat_Mes,$Z6) | AC6: =SUMIFS(Fat_ValorPerd,Fat_Mes,$Z6) | AD6: =SUMIFS(Fat_LucroLiq,Fat_Mes,$Z6)
A7: =IF('Cadastro Produtos'!$B7="","",'Cadastro Produtos'!$B7) | B7: =IF($A7="","",SUMIFS(Fat_PesoAntes,Fat_Produto,$A7)) | C7: =IF($A7="","",SUMIFS(Fat_PesoVend,Fat_Produto,$A7)) | D7: =IF($A7="","",SUMIFS(Fat_PesoPerd,Fat_Produto,$A7)) | E7: =IF($A7="","",SUMIFS(Fat_ValorPerd,Fat_Produto,$A7)) | F7: =IF($A7="","",SUMIFS(Fat_Receita,Fat_Produto,$A7)) | G7: =IF($A7="","",SUMIFS(Fat_LucroLiq,Fat_Produto,$A7)) | H7: =IF($A7="","",IFERROR($D7/$B7,0)) | I7: =IF($A7="","",IFERROR($G7/$F7,0)) | J7: =IF($A7="","",$E7+ROW()/1000000) | K7: =IF($A7="","",$G7+ROW()/1000000) | L7: =IF($A7="","",IF($H7>MetaPerdaMax,"ALERTA","OK")) | N7: Carlos | O7: =SUMIFS(Fat_PesoAntes,Fat_Func,$N7) | P7: =SUMIFS(Fat_PesoPerd,Fat_Func,$N7) | Q7: =SUMIFS(Fat_ValorPerd,Fat_Func,$N7) | R7: =IFERROR($P7/$O7,0) | T7: Distribuidora C | U7: =SUMIFS(Fat_PesoAntes,Fat_Fornecedor,$T7) | V7: =SUMIFS(Fat_PesoPerd,Fat_Fornecedor,$T7) | W7: =SUMIFS(Fat_ValorPerd,Fat_Fornecedor,$T7) | X7: =IFERROR($V7/$U7,0) | Z7: 46082 | AA7: =SUMIFS(Fat_PesoVend,Fat_Mes,$Z7) | AB7: =SUMIFS(Fat_PesoPerd,Fat_Mes,$Z7) | AC7: =SUMIFS(Fat_ValorPerd,Fat_Mes,$Z7) | AD7: =SUMIFS(Fat_LucroLiq,Fat_Mes,$Z7)
A8: =IF('Cadastro Produtos'!$B8="","",'Cadastro Produtos'!$B8) | B8: =IF($A8="","",SUMIFS(Fat_PesoAntes,Fat_Produto,$A8)) | C8: =IF($A8="","",SUMIFS(Fat_PesoVend,Fat_Produto,$A8)) | D8: =IF($A8="","",SUMIFS(Fat_PesoPerd,Fat_Produto,$A8)) | E8: =IF($A8="","",SUMIFS(Fat_ValorPerd,Fat_Produto,$A8)) | F8: =IF($A8="","",SUMIFS(Fat_Receita,Fat_Produto,$A8)) | G8: =IF($A8="","",SUMIFS(Fat_LucroLiq,Fat_Produto,$A8)) | H8: =IF($A8="","",IFERROR($D8/$B8,0)) | I8: =IF($A8="","",IFERROR($G8/$F8,0)) | J8: =IF($A8="","",$E8+ROW()/1000000) | K8: =IF($A8="","",$G8+ROW()/1000000) | L8: =IF($A8="","",IF($H8>MetaPerdaMax,"ALERTA","OK")) | N8: Ana | O8: =SUMIFS(Fat_PesoAntes,Fat_Func,$N8) | P8: =SUMIFS(Fat_PesoPerd,Fat_Func,$N8) | Q8: =SUMIFS(Fat_ValorPerd,Fat_Func,$N8) | R8: =IFERROR($P8/$O8,0) | Z8: 46113 | AA8: =SUMIFS(Fat_PesoVend,Fat_Mes,$Z8) | AB8: =SUMIFS(Fat_PesoPerd,Fat_Mes,$Z8) | AC8: =SUMIFS(Fat_ValorPerd,Fat_Mes,$Z8) | AD8: =SUMIFS(Fat_LucroLiq,Fat_Mes,$Z8)
A9: =IF('Cadastro Produtos'!$B9="","",'Cadastro Produtos'!$B9) | B9: =IF($A9="","",SUMIFS(Fat_PesoAntes,Fat_Produto,$A9)) | C9: =IF($A9="","",SUMIFS(Fat_PesoVend,Fat_Produto,$A9)) | D9: =IF($A9="","",SUMIFS(Fat_PesoPerd,Fat_Produto,$A9)) | E9: =IF($A9="","",SUMIFS(Fat_ValorPerd,Fat_Produto,$A9)) | F9: =IF($A9="","",SUMIFS(Fat_Receita,Fat_Produto,$A9)) | G9: =IF($A9="","",SUMIFS(Fat_LucroLiq,Fat_Produto,$A9)) | H9: =IF($A9="","",IFERROR($D9/$B9,0)) | I9: =IF($A9="","",IFERROR($G9/$F9,0)) | J9: =IF($A9="","",$E9+ROW()/1000000) | K9: =IF($A9="","",$G9+ROW()/1000000) | L9: =IF($A9="","",IF($H9>MetaPerdaMax,"ALERTA","OK")) | N9: Pedro | O9: =SUMIFS(Fat_PesoAntes,Fat_Func,$N9) | P9: =SUMIFS(Fat_PesoPerd,Fat_Func,$N9) | Q9: =SUMIFS(Fat_ValorPerd,Fat_Func,$N9) | R9: =IFERROR($P9/$O9,0) | Z9: 46143 | AA9: =SUMIFS(Fat_PesoVend,Fat_Mes,$Z9) | AB9: =SUMIFS(Fat_PesoPerd,Fat_Mes,$Z9) | AC9: =SUMIFS(Fat_ValorPerd,Fat_Mes,$Z9) | AD9: =SUMIFS(Fat_LucroLiq,Fat_Mes,$Z9)
A10: =IF('Cadastro Produtos'!$B10="","",'Cadastro Produtos'!$B10) | B10: =IF($A10="","",SUMIFS(Fat_PesoAntes,Fat_Produto,$A10)) | C10: =IF($A10="","",SUMIFS(Fat_PesoVend,Fat_Produto,$A10)) | D10: =IF($A10="","",SUMIFS(Fat_PesoPerd,Fat_Produto,$A10)) | E10: =IF($A10="","",SUMIFS(Fat_ValorPerd,Fat_Produto,$A10)) | F10: =IF($A10="","",SUMIFS(Fat_Receita,Fat_Produto,$A10)) | G10: =IF($A10="","",SUMIFS(Fat_LucroLiq,Fat_Produto,$A10)) | H10: =IF($A10="","",IFERROR($D10/$B10,0)) | I10: =IF($A10="","",IFERROR($G10/$F10,0)) | J10: =IF($A10="","",$E10+ROW()/1000000) | K10: =IF($A10="","",$G10+ROW()/1000000) | L10: =IF($A10="","",IF($H10>MetaPerdaMax,"ALERTA","OK")) | N10: Rafael | O10: =SUMIFS(Fat_PesoAntes,Fat_Func,$N10) | P10: =SUMIFS(Fat_PesoPerd,Fat_Func,$N10) | Q10: =SUMIFS(Fat_ValorPerd,Fat_Func,$N10) | R10: =IFERROR($P10/$O10,0) | Z10: 46174 | AA10: =SUMIFS(Fat_PesoVend,Fat_Mes,$Z10) | AB10: =SUMIFS(Fat_PesoPerd,Fat_Mes,$Z10) | AC10: =SUMIFS(Fat_ValorPerd,Fat_Mes,$Z10) | AD10: =SUMIFS(Fat_LucroLiq,Fat_Mes,$Z10)
A11: =IF('Cadastro Produtos'!$B11="","",'Cadastro Produtos'!$B11) | B11: =IF($A11="","",SUMIFS(Fat_PesoAntes,Fat_Produto,$A11)) | C11: =IF($A11="","",SUMIFS(Fat_PesoVend,Fat_Produto,$A11)) | D11: =IF($A11="","",SUMIFS(Fat_PesoPerd,Fat_Produto,$A11)) | E11: =IF($A11="","",SUMIFS(Fat_ValorPerd,Fat_Produto,$A11)) | F11: =IF($A11="","",SUMIFS(Fat_Receita,Fat_Produto,$A11)) | G11: =IF($A11="","",SUMIFS(Fat_LucroLiq,Fat_Produto,$A11)) | H11: =IF($A11="","",IFERROR($D11/$B11,0)) | I11: =IF($A11="","",IFERROR($G11/$F11,0)) | J11: =IF($A11="","",$E11+ROW()/1000000) | K11: =IF($A11="","",$G11+ROW()/1000000) | L11: =IF($A11="","",IF($H11>MetaPerdaMax,"ALERTA","OK")) | Z11: 46204 | AA11: =SUMIFS(Fat_PesoVend,Fat_Mes,$Z11) | AB11: =SUMIFS(Fat_PesoPerd,Fat_Mes,$Z11) | AC11: =SUMIFS(Fat_ValorPerd,Fat_Mes,$Z11) | AD11: =SUMIFS(Fat_LucroLiq,Fat_Mes,$Z11)
